Workbook
Name Slicer_Gender: #N/A
Name Slicer_Payment_Type: #N/A
Name Slicer_Region: #N/A
Name Slicer_Years__Order_Date: #N/A

Sheet Customer_Dim
A1: Customer_ID | B1: Customer_ID | C1: Name | D1: Age | E1: Gender | F1: City | G1: State | H1: Country | I1: Loyalty_Level
A2: CUST1000 | B2: CUST1000 | C2: Sheena Bonilla | D2: 26 | E2: Female | F2: Donaldton | G2: North Carolina | H2: USA | I2: Platinum
A3: CUST1001 | B3: CUST1001 | C3: Eugene Nelson | D3: 29 | E3: Female | F3: Phillipsmouth | G3: North Dakota | H3: USA | I3: Platinum
A4: CUST1002 | B4: CUST1002 | C4: Dr. Benjamin Price | D4: 59 | E4: Female | F4: Kylebury | G4: Alabama | H4: USA | I4: Platinum
A5: CUST1003 | B5: CUST1003 | C5: Jeremy Harris | D5: 64 | E5: Female | F5: Thomastown | G5: Ohio | H5: USA | I5: Bronze
A6: CUST1004 | B6: CUST1004 | C6: Caroline Collins | D6: 24 | E6: Male | F6: Nicholasshire | G6: California | H6: USA | I6: Silver
A7: CUST1005 | B7: CUST1005 | C7: Christine Vaughn | D7: 29 | E7: Female | F7: East Amandamouth | G7: Oregon | H7: USA | I7: Bronze
A8: CUST1006 | B8: CUST1006 | C8: Amber Jackson | D8: 29 | E8: Female | F8: Deborahborough | G8: South Dakota | H8: USA | I8: Platinum
A9: CUST1007 | B9: CUST1007 | C9: Daniel Boyd | D9: 53 | E9: Female | F9: West Pamelafurt | G9: West Virginia | H9: USA | I9: Bronze
A10: CUST1008 | B10: CUST1008 | C10: Melissa Howard | D10: 64 | E10: Male | F10: Maynardton | G10: New Hampshire | H10: USA | I10: Gold
A11: CUST1009 | B11: CUST1009 | C11: Ms. Maria Leach | D11: 53 | E11: Male | F11: Melissashire | G11: Pennsylvania | H11: USA | I11: Platinum
A12: CUST1010 | B12: CUST1010 | C12: Dominic Page | D12: 28 | E12: Female | F12: Port Michaelburgh | G12: Pennsylvania | H12: USA | I12: Bronze
A13: CUST1011 | B13: CUST1011 | C13: Brian Lopez | D13: 55 | E13: Female | F13: East Krista | G13: New York | H13: USA | I13: Gold
... A501: CUST1499 | B501: CUST1499 | C501: Philip Pennington | D501: 27 | E501: Female | F501: East Valerieview | G501: Oregon | H501: USA | I501: Platinum

Sheet Product_Dim
A1: Product_ID | B1: Product_Name | C1: Category | D1: Sub_Category | E1: Brand | F1: Cost | G1: Stock
A2: PROD0 | B2: Brother Laser Printer | C2: Electronics | D2: Computer | E2: Hunt Inc | F2: 112.42 | G2: 416
A3: PROD1 | B3: Men's Graphic T-Shirt | C3: Clothing | D3: Tops | E3: Terry-Moore | F3: 342.56 | G3: 181
A4: PROD2 | B4: Women's Casual Hoodie | C4: Clothing | D4: Outerwear | E4: Sims Inc | F4: 254.62087 | G4: 352
A5: PROD3 | B5: Men's Running Jacket | C5: Clothing | D5: Outerwear | E5: Pineda Ltd | F5: 364.67 | G5: 452
A6: PROD4 | B6: Women's Yoga Pants | C6: Clothing | D6: Bottoms | E6: Gonzales-Davis | F6: 306.46 | G6: 487
A7: PROD5 | B7: Men's Leather Belt | C7: Clothing | D7: Accessories | E7: Baldwin, Garza and Gonzalez | F7: 261 | G7: 59
A8: PROD6 | B8: Herbal Face Moisturizer | C8: Beauty | D8: Skincare | E8: Davidson PLC | F8: 312.8 | G8: 350
A9: PROD7 | B9: LED Table Lamp | C9: Home | D9: Lighting | E9: Harrell LLC | F9: 218.86 | G9: 170
A10: PROD8 | B10: Wireless Bluetooth Earbuds | C10: Electronics | D10: Audio | E10: Perez-Johnston | F10: 439.07 | G10: 142
A11: PROD9 | B11: Adjustable Dumbbell Set | C11: Sports | D11: Fitness | E11: Hill PLC | F11: 495.72 | G11: 323
A12: PROD10 | B12: Ceramic Kitchen Bowl Set | C12: Home | D12: Kitchen | E12: Hamilton Group | F12: 298.86 | G12: 308
A13: PROD11 | B13: HD Smart TV Stick | C13: Electronics | D13: Accessories | E13: Gibson, Hobbs and Weaver | F13: 449.4 | G13: 270.80233
... A101: PROD99 | B101: Stainless Steel Cookware Set | C101: Home | D101: Kitchen | E101: Campbell Ltd | F101: 201.41 | G101: 146

Sheet Store_Dim
A1: Store_ID | B1: Store_Name | C1: Region | D1: City | E1: Store_Type
A2: STORE0 | B2: Rivera-Warner | C2: East | D2: Washingtonfurt | E2: Flagship
A3: STORE1 | B3: Martinez, Adkins and Johnson | C3: North | D3: Danielmouth | E3: Flagship
A4: STORE2 | B4: Black-Horn | C4: South | D4: North Nancyview | E4: Outlet
A5: STORE3 | B5: Johnson-Wright | C5: North | D5: Hoodberg | E5: Outlet
A6: STORE4 | B6: Alexander Group | C6: South | D6: Port Sharon | E6: Online
A7: STORE5 | B7: Gray Ltd | C7: North | D7: New Michaelchester | E7: Outlet
A8: STORE6 | B8: Benson-Elliott | C8: East | D8: Port Josephberg | E8: Online
A9: STORE7 | B9: Martinez-Mullins | C9: South | D9: Williamsfurt | E9: Online
A10: STORE8 | B10: Bean, Jones and Park | C10: West | D10: Thompsonborough | E10: Online
A11: STORE9 | B11: Moore, Padilla and Butler | C11: South | D11: East Johnstad | E11: Flagship
A12: STORE10 | B12: Hill, Wagner and Ballard | C12: East | D12: East Davidville | E12: Online
... A21: STORE19 | B21: Mann-Austin | C21: East | D21: Vasquezborough | E21: Online

Sheet worksheet.
A1: Sales_ID | B1: Order_Date | C1: Customer_ID | D1: Product_ID | E1: Store_ID | F1: Quantity | G1: Unit_Price | H1: Discount | I1: Payment_Type | J1: Total_Amount | K1: Name | L1: Age | M1: Gender | N1: City | O1: State | P1: Country | Q1: Loyalty_Level | S1: Quantity | T1: Unit_Price | U1: Discount | V1: Total_Amount | X1: Quantity | Y1: Unit_Price | Z1: Discount | AA1: Total_Amount
A2: SALE0 | B2: 45480 | C2: CUST1409 | D2: PROD97 | E2: STORE3 | F2: 1 | G2: 218.04 | H2: 0.09 | I2: Credit Card | J2: 198.4164 | K2: Sarah Smith | L2: 48 | M2: {=VLOOKUP(C2:C2001,Table3[#All],4,1)} -> Female | N2: =VLOOKUP(C:C,Customer_Dim!B:I,5,1) -> Kathleenport | O2: =VLOOKUP(C:C,Customer_Dim!B:I,6,1) -> Wyoming | P2: =VLOOKUP(C:C,Customer_Dim!B:I,7,1) -> USA | Q2: =VLOOKUP(C:C,Customer_Dim!B:I,8,1) -> Gold | S2: 1 | T2: 218.04 | U2: 0.09 | V2: 198.4164 | X2: 1 | Y2: 218.04 | Z2: 0.09 | AA2: 198.4164
A3: SALE1 | B3: 45285 | C3: CUST1467 | D3: PROD74 | E3: STORE17 | F3: 3 | G3: 104.47 | H3: 0.27 | I3: PayPal | J3: 228.7893 | K3: Michael Foley | L3: 45 | M3: Male | N3: =VLOOKUP(C:C,Customer_Dim!B:I,5,1) -> Oneillfurt | O3: =VLOOKUP(C:C,Customer_Dim!B:I,6,1) -> Vermont | P3: =VLOOKUP(C:C,Customer_Dim!B:I,7,1) -> USA | Q3: =VLOOKUP(C:C,Customer_Dim!B:I,8,1) -> Gold | S3: 3 | T3: 104.47 | U3: 0.27 | V3: 228.7893 | X3: 3 | Y3: 104.47 | Z3: 0.27 | AA3: 228.7893
A4: SALE2 | B4: 45446 | C4: CUST1056 | D4: PROD49 | E4: STORE8 | F4: 4 | G4: 914.05 | H4: 0.25 | I4: Credit Card | J4: 2742.15 | K4: Christopher Sutton | L4: 43 | M4: Female | N4: =VLOOKUP(C:C,Customer_Dim!B:I,5,1) -> Deborahberg | O4: =VLOOKUP(C:C,Customer_Dim!B:I,6,1) -> Pennsylvania | P4: =VLOOKUP(C:C,Customer_Dim!B:I,7,1) -> USA | Q4: =VLOOKUP(C:C,Customer_Dim!B:I,8,1) -> Gold | S4: 4 | T4: 914.05 | U4: 0.25 | V4: 2742.15 | X4: 4 | Y4: 914.05 | Z4: 0.25 | AA4: 2742.15
A5: SALE3 | B5: 45259 | C5: CUST1346 | D5: PROD76 | E5: STORE8 | F5: 1 | G5: 921.51 | H5: 0.16 | I5: COD | J5: 774.0684 | K5: John Jordan | L5: 39 | M5: Female | N5: =VLOOKUP(C:C,Customer_Dim!B:I,5,1) -> Port Crystalberg | O5: =VLOOKUP(C:C,Customer_Dim!B:I,6,1) -> Tennessee | P5: =VLOOKUP(C:C,Customer_Dim!B:I,7,1) -> USA | Q5: =VLOOKUP(C:C,Customer_Dim!B:I,8,1) -> Platinum | S5: 1 | T5: 921.51 | U5: 0.16 | V5: 774.0684 | X5: 1 | Y5: 921.51 | Z5: 0.16 | AA5: 774.0684
A6: SALE4 | B6: 45297 | C6: CUST1493 | D6: PROD59 | E6: STORE5 | F6: 3 | G6: 745.3 | H6: 0.18 | I6: Credit Card | J6: 1833.438 | K6: Amanda Powell | L6: 21 | M6: Male | N6: =VLOOKUP(C:C,Customer_Dim!B:I,5,1) -> South William | O6: =VLOOKUP(C:C,Customer_Dim!B:I,6,1) -> Alabama | P6: =VLOOKUP(C:C,Customer_Dim!B:I,7,1) -> USA | Q6: =VLOOKUP(C:C,Customer_Dim!B:I,8,1) -> Silver | S6: 3 | T6: 745.3 | U6: 0.18 | V6: 1833.438 | X6: 3 | Y6: 745.3 | Z6: 0.18 | AA6: 1833.438
A7: SALE5 | B7: 45499 | C7: CUST1116 | D7: PROD15 | E7: STORE7 | F7: 3 | G7: 147.01 | H7: 0.19 | I7: COD | J7: 357.2343 | K7: Anthony Phillips | L7: 21 | M7: Female | N7: =VLOOKUP(C:C,Customer_Dim!B:I,5,1) -> North Davidport | O7: =VLOOKUP(C:C,Customer_Dim!B:I,6,1) -> Rhode Island | P7: =VLOOKUP(C:C,Customer_Dim!B:I,7,1) -> USA | Q7: =VLOOKUP(C:C,Customer_Dim!B:I,8,1) -> Platinum | S7: 3 | T7: 147.01 | U7: 0.19 | V7: 357.2343 | X7: 3 | Y7: 147.01 | Z7: 0.19 | AA7: 357.2343
A8: SALE6 | B8: 45850 | C8: CUST1016 | D8: PROD56 | E8: STORE4 | F8: 2 | G8: 785.31 | H8: 0.15 | I8: PayPal | J8: 1335.027 | K8: John Scott | L8: 60 | M8: Female | N8: =VLOOKUP(C:C,Customer_Dim!B:I,5,1) -> South Christopher | O8: =VLOOKUP(C:C,Customer_Dim!B:I,6,1) -> Pennsylvania | P8: =VLOOKUP(C:C,Customer_Dim!B:I,7,1) -> USA | Q8: =VLOOKUP(C:C,Customer_Dim!B:I,8,1) -> Bronze | S8: 2 | T8: 785.31 | U8: 0.15 | V8: 1335.027 | X8: 2 | Y8: 785.31 | Z8: 0.15 | AA8: 1335.027
A9: SALE7 | B9: 45248 | C9: CUST1152 | D9: PROD70 | E9: STORE8 | F9: 4 | G9: 342.39 | H9: 0.23 | I9: PayPal | J9: 1054.5612 | K9: Patrick Roberts | L9: 31 | M9: Male | N9: =VLOOKUP(C:C,Customer_Dim!B:I,5,1) -> Jaredville | O9: =VLOOKUP(C:C,Customer_Dim!B:I,6,1) -> Missouri | P9: =VLOOKUP(C:C,Customer_Dim!B:I,7,1) -> USA | Q9: =VLOOKUP(C:C,Customer_Dim!B:I,8,1) -> Platinum | S9: 4 | T9: 342.39 | U9: 0.23 | V9: 1054.5612 | X9: 4 | Y9: 342.39 | Z9: 0.23 | AA9: 1054.5612
A10: SALE8 | B10: 45781 | C10: CUST1187 | D10: PROD99 | E10: STORE5 | F10: 2.4796175 | G10: 448.25 | H10: 0.07 | I10: PayPal | J10: 1250.6175 | K10: Dr. Suzanne Bullock | L10: 42 | M10: Male | N10: =VLOOKUP(C:C,Customer_Dim!B:I,5,1) -> Lake Blaketon | O10: =VLOOKUP(C:C,Customer_Dim!B:I,6,1) -> Alabama | P10: =VLOOKUP(C:C,Customer_Dim!B:I,7,1) -> USA | Q10: =VLOOKUP(C:C,Customer_Dim!B:I,8,1) -> Platinum | T10: 448.25 | U10: 0.07 | V10: 1250.6175 | X10: 2.4796175 | Y10: 448.25 | Z10: 0.07 | AA10: 1250.6175
A11: SALE9 | B11: 45869 | C11: CUST1464 | D11: PROD33 | E11: STORE0 | F11: 2 | G11: 873.17 | H11: 0.23 | I11: PayPal | J11: 1344.6818 | K11: David Pierce | L11: 28 | M11: Female | N11: =VLOOKUP(C:C,Customer_Dim!B:I,5,1) -> Grayland | O11: =VLOOKUP(C:C,Customer_Dim!B:I,6,1) -> Washington | P11: =VLOOKUP(C:C,Customer_Dim!B:I,7,1) -> USA | Q11: =VLOOKUP(C:C,Customer_Dim!B:I,8,1) -> Platinum | S11: 2 | T11: 873.17 | U11: 0.23 | V11: 1344.6818 | X11: 2 | Y11: 873.17 | Z11: 0.23 | AA11: 1344.6818
A12: SALE10 | B12: 45335 | C12: CUST1065 | D12: PROD24 | E12: STORE14 | F12: 1 | G12: 278.63 | H12: 0.07 | I12: Credit Card | J12: 259.1259 | K12: Michael Thomas | L12: 27 | M12: Female | N12: =VLOOKUP(C:C,Customer_Dim!B:I,5,1) -> Woodmouth | O12: =VLOOKUP(C:C,Customer_Dim!B:I,6,1) -> Nevada | P12: =VLOOKUP(C:C,Customer_Dim!B:I,7,1) -> USA | Q12: =VLOOKUP(C:C,Customer_Dim!B:I,8,1) -> Silver | S12: 1 | T12: 278.63 | U12: 0.07 | V12: 259.1259 | X12: 1 | Y12: 278.63 | Z12: 0.07 | AA12: 259.1259
A13: SALE11 | B13: 45801 | C13: CUST1320 | D13: PROD39 | E13: STORE1 | F13: 4 | G13: 286.92 | H13: 0.17 | I13: Credit Card | J13: 952.5744 | K13: Jessica Gonzalez | L13: 21 | M13: Female | N13: =VLOOKUP(C:C,Customer_Dim!B:I,5,1) -> South Darrenland | O13: =VLOOKUP(C:C,Customer_Dim!B:I,6,1) -> Iowa | P13: =VLOOKUP(C:C,Customer_Dim!B:I,7,1) -> USA | Q13: =VLOOKUP(C:C,Customer_Dim!B:I,8,1) -> Bronze | S13: 4 | T13: 286.92 | U13: 0.17 | V13: 952.5744 | X13: 4 | Y13: 286.92 | Z13: 0.17 | AA13: 952.5744
A14: SALE12 | B14: 45528 | C14: CUST1237 | D14: PROD88 | E14: STORE4 | F14: 4 | G14: 644.58 | H14: 0.01 | I14: Credit Card | J14: 2552.5368 | K14: Wesley Short | L14: 40 | M14: Male | N14: =VLOOKUP(C:C,Customer_Dim!B:I,5,1) -> Susanstad | O14: =VLOOKUP(C:C,Customer_Dim!B:I,6,1) -> Montana | P14: =VLOOKUP(C:C,Customer_Dim!B:I,7,1) -> USA | Q14: =VLOOKUP(C:C,Customer_Dim!B:I,8,1) -> Gold | S14: 4 | T14: 644.58 | U14: 0.01 | V14: 2552.5368 | X14: 4 | Y14: 644.58 | Z14: 0.01 | AA14: 2552.5368
A15: SALE13 | B15: 45875 | C15: CUST1443 | D15: PROD34 | E15: STORE16 | F15: 2 | G15: 316.9 | H15: 0.3 | I15: PayPal | J15: 443.66 | K15: Adam Castro | L15: 19 | M15: Male | N15: =VLOOKUP(C:C,Customer_Dim!B:I,5,1) -> New Donnabury | O15: =VLOOKUP(C:C,Customer_Dim!B:I,6,1) -> Texas | P15: =VLOOKUP(C:C,Customer_Dim!B:I,7,1) -> USA | Q15: =VLOOKUP(C:C,Customer_Dim!B:I,8,1) -> Silver | S15: 2 | T15: 316.9 | U15: 0.3 | V15: 443.66 | X15: 2 | Y15: 316.9 | Z15: 0.3 | AA15: 443.66
A16: SALE14 | B16: 45829 | C16: CUST1348 | D16: PROD24 | E16: STORE15 | F16: 4 | G16: 403.47 | H16: 0.29 | I16: PayPal | J16: 1145.8548 | K16: Sherry Cabrera | L16: 31 | M16: Male | N16: =VLOOKUP(C:C,Customer_Dim!B:I,5,1) -> Shannonview | O16: =VLOOKUP(C:C,Customer_Dim!B:I,6,1) -> Pennsylvania | P16: =VLOOKUP(C:C,Customer_Dim!B:I,7,1) -> USA | Q16: =VLOOKUP(C:C,Customer_Dim!B:I,8,1) -> Silver | S16: 4 | T16: 403.47 | U16: 0.29 | V16: 1145.8548 | X16: 4 | Y16: 403.47 | Z16: 0.29 | AA16: 1145.8548
A17: SALE15 | B17: 45636 | C17: CUST1435 | D17: PROD36 | E17: STORE9 | F17: 2.4785462 | G17: 871.34 | H17: 0.04 | I17: COD | J17: 2509.4592 | K17: Lindsay Beasley | L17: 61 | M17: Male | N17: =VLOOKUP(C:C,Customer_Dim!B:I,5,1) -> Wesleyhaven | O17: =VLOOKUP(C:C,Customer_Dim!B:I,6,1) -> Idaho | P17: =VLOOKUP(C:C,Customer_Dim!B:I,7,1) -> USA | Q17: =VLOOKUP(C:C,Customer_Dim!B:I,8,1) -> Silver | T17: 871.34 | U17: 0.04 | V17: 2509.4592 | X17: 2.4785462 | Y17: 871.34 | Z17: 0.04 | AA17: 2509.4592
A18: SALE16 | B18: 45913 | C18: CUST1276 | D18: PROD65 | E18: STORE19 | F18: 2 | G18: 451.98 | H18: 0.25 | I18: Credit Card | J18: 677.97 | K18: Arthur Warren | L18: 22 | M18: Female | N18: =VLOOKUP(C:C,Customer_Dim!B:I,5,1) -> Ericshire | O18: =VLOOKUP(C:C,Customer_Dim!B:I,6,1) -> Nevada | P18: =VLOOKUP(C:C,Customer_Dim!B:I,7,1) -> USA | Q18: =VLOOKUP(C:C,Customer_Dim!B:I,8,1) -> Gold | S18: 2 | T18: 451.98 | U18: 0.25 | V18: 677.97 | X18: 2 | Y18: 451.98 | Z18: 0.25 | AA18: 677.97
A19: SALE17 | B19: 45637 | C19: CUST1079 | D19: PROD27 | E19: STORE4 | F19: 2 | G19: 502.69 | H19: 0.23 | I19: Credit Card | J19: 774.1426 | K19: Molly Gardner | L19: 61 | M19: Female | N19: =VLOOKUP(C:C,Customer_Dim!B:I,5,1) -> Nicoleborough | O19: =VLOOKUP(C:C,Customer_Dim!B:I,6,1) -> Arkansas | P19: =VLOOKUP(C:C,Customer_Dim!B:I,7,1) -> USA | Q19: =VLOOKUP(C:C,Customer_Dim!B:I,8,1) -> Platinum | S19: 2 | T19: 502.69 | U19: 0.23 | V19: 774.1426 | X19: 2 | Y19: 502.69 | Z19: 0.23 | AA19: 774.1426
A20: SALE18 | B20: 45517 | C20: CUST1094 | D20: PROD39 | E20: STORE4 | F20: 2 | G20: 559.23 | H20: 0.25 | I20: COD | J20: 838.845 | K20: David Patterson | L20: 62 | M20: Female | N20: =VLOOKUP(C:C,Customer_Dim!B:I,5,1) -> New Amyport | O20: =VLOOKUP(C:C,Customer_Dim!B:I,6,1) -> Nevada | P20: =VLOOKUP(C:C,Customer_Dim!B:I,7,1) -> USA | Q20: =VLOOKUP(C:C,Customer_Dim!B:I,8,1) -> Gold | S20: 2 | T20: 559.23 | U20: 0.25 | V20: 838.845 | X20: 2 | Y20: 559.23 | Z20: 0.25 | AA20: 838.845
A21: SALE19 | B21: 45369 | C21: CUST1239 | D21: PROD60 | E21: STORE13 | F21: 4 | G21: 513.95973 | H21: 0.04 | I21: COD | J21: 1782.4512 | K21: Maria Hill | L21: 59 | M21: Female | N21: =VLOOKUP(C:C,Customer_Dim!B:I,5,1) -> Zamoraborough | O21: =VLOOKUP(C:C,Customer_Dim!B:I,6,1) -> Nevada | P21: =VLOOKUP(C:C,Customer_Dim!B:I,7,1) -> USA | Q21: =VLOOKUP(C:C,Customer_Dim!B:I,8,1) -> Platinum | S21: 4 | U21: 0.04 | V21: 1782.4512 | X21: 4 | Y21: 513.95973 | Z21: 0.04 | AA21: 1782.4512
A22: SALE20 | B22: 45843 | C22: CUST1144 | D22: PROD72 | E22: STORE17 | F22: 3 | G22: 986.04 | H22: 0.27 | I22: COD | J22: 2159.4276 | K22: Justin Cross | L22: 46 | M22: Male | N22: =VLOOKUP(C:C,Customer_Dim!B:I,5,1) -> North Anthonychester | O22: =VLOOKUP(C:C,Customer_Dim!B:I,6,1) -> Nevada | P22: =VLOOKUP(C:C,Customer_Dim!B:I,7,1) -> USA | Q22: =VLOOKUP(C:C,Customer_Dim!B:I,8,1) -> Bronze | S22: 3 | T22: 986.04 | U22: 0.27 | V22: 2159.4276 | X22: 3 | Y22: 986.04 | Z22: 0.27 | AA22: 2159.4276
A23: SALE21 | B23: 45447 | C23: CUST1396 | D23: PROD43 | E23: STORE18 | F23: 1 | G23: 589.56 | H23: 0.22 | I23: Credit Card | J23: 459.8568 | K23: Alexander Byrd | L23: 62 | M23: Female | N23: =VLOOKUP(C:C,Customer_Dim!B:I,5,1) -> Parkerview | O23: =VLOOKUP(C:C,Customer_Dim!B:I,6,1) -> New York | P23: =VLOOKUP(C:C,Customer_Dim!B:I,7,1) -> USA | Q23: =VLOOKUP(C:C,Customer_Dim!B:I,8,1) -> Silver | S23: 1 | T23: 589.56 | U23: 0.22 | V23: 459.8568 | X23: 1 | Y23: 589.56 | Z23: 0.22 | AA23: 459.8568
A24: SALE22 | B24: 45394 | C24: CUST1476 | D24: PROD69 | E24: STORE10 | F24: 3 | G24: 979.42 | H24: 0.03 | I24: PayPal | J24: 2850.1122 | K24: Elizabeth Foster | L24: 41 | M24: Female | N24: =VLOOKUP(C:C,Customer_Dim!B:I,5,1) -> Anthonymouth | O24: =VLOOKUP(C:C,Customer_Dim!B:I,6,1) -> Oklahoma | P24: =VLOOKUP(C:C,Customer_Dim!B:I,7,1) -> USA | Q24: =VLOOKUP(C:C,Customer_Dim!B:I,8,1) -> Gold | S24: 3 | T24: 979.42 | U24: 0.03 | V24: 2850.1122 | X24: 3 | Y24: 979.42 | Z24: 0.03 | AA24: 2850.1122
A25: SALE23 | B25: 45466 | C25: CUST1368 | D25: PROD12 | E25: STORE8 | F25: 1 | G25: 719.28 | H25: 0.08 | I25: Credit Card | J25: 661.7376 | K25: Miranda King | L25: 20 | M25: Female | N25: =VLOOKUP(C:C,Customer_Dim!B:I,5,1) -> West Mathew | O25: =VLOOKUP(C:C,Customer_Dim!B:I,6,1) -> New York | P25: =VLOOKUP(C:C,Customer_Dim!B:I,7,1) -> USA | Q25: =VLOOKUP(C:C,Customer_Dim!B:I,8,1) -> Platinum | S25: 1 | T25: 719.28 | U25: 0.08 | V25: 661.7376 | X25: 1 | Y25: 719.28 | Z25: 0.08 | AA25: 661.7376
A26: SALE24 | B26: 45908 | C26: CUST1186 | D26: PROD67 | E26: STORE6 | F26: 3 | G26: 77.6 | H26: 0.07 | I26: Credit Card | J26: 216.504 | K26: Jennifer Pruitt | L26: 60 | M26: Female | N26: =VLOOKUP(C:C,Customer_Dim!B:I,5,1) -> East Justin | O26: =VLOOKUP(C:C,Customer_Dim!B:I,6,1) -> Missouri | P26: =VLOOKUP(C:C,Customer_Dim!B:I,7,1) -> USA | Q26: =VLOOKUP(C:C,Customer_Dim!B:I,8,1) -> Silver | S26: 3 | T26: 77.6 | U26: 0.07 | V26: 216.504 | X26: 3 | Y26: 77.6 | Z26: 0.07 | AA26: 216.504
A27: SALE25 | B27: 45552 | C27: CUST1381 | D27: PROD5 | E27: STORE3 | F27: 4 | G27: 852.71 | H27: 0.14 | I27: PayPal | J27: 2933.3224 | K27: Erika Padilla | L27: 20 | M27: Female | N27: =VLOOKUP(C:C,Customer_Dim!B:I,5,1) -> Andrewsland | O27: =VLOOKUP(C:C,Customer_Dim!B:I,6,1) -> Alabama | P27: =VLOOKUP(C:C,Customer_Dim!B:I,7,1) -> USA | Q27: =VLOOKUP(C:C,Customer_Dim!B:I,8,1) -> Silver | S27: 4 | T27: 852.71 | U27: 0.14 | V27: 2933.3224 | X27: 4 | Y27: 852.71 | Z27: 0.14 | AA27: 2933.3224
A28: SALE26 | B28: 45294 | C28: CUST1213 | D28: PROD98 | E28: STORE8 | F28: 4 | G28: 156.16 | H28: 0.14786802 | I28: Credit Card | J28: 599.6544 | K28: Stuart Johnson | L28: 61 | M28: Male | N28: =VLOOKUP(C:C,Customer_Dim!B:I,5,1) -> West Markport | O28: =VLOOKUP(C:C,Customer_Dim!B:I,6,1) -> North Dakota | P28: =VLOOKUP(C:C,Customer_Dim!B:I,7,1) -> USA | Q28: =VLOOKUP(C:C,Customer_Dim!B:I,8,1) -> Platinum | S28: 4 | T28: 156.16 | V28: 599.6544 | X28: 4 | Y28: 156.16 | Z28: 0.14786802 | AA28: 599.6544
A29: SALE27 | B29: 45710 | C29: CUST1200 | D29: PROD77 | E29: STORE8 | F29: 3 | G29: 815.49 | H29: 0.17 | I29: Credit Card | J29: 2030.5701 | K29: Anna Perez | L29: 25 | M29: Female | N29: =VLOOKUP(C:C,Customer_Dim!B:I,5,1) -> South Jerry | O29: =VLOOKUP(C:C,Customer_Dim!B:I,6,1) -> Maine | P29: =VLOOKUP(C:C,Customer_Dim!B:I,7,1) -> USA | Q29: =VLOOKUP(C:C,Customer_Dim!B:I,8,1) -> Platinum | S29: 3 | T29: 815.49 | U29: 0.17 | V29: 2030.5701 | X29: 3 | Y29: 815.49 | Z29: 0.17 | AA29: 2030.5701
A30: SALE28 | B30: 45923 | C30: CUST1148 | D30: PROD13 | E30: STORE2 | F30: 2 | G30: 74.21 | H30: 0.11 | I30: PayPal | J30: 132.0938 | K30: Theresa Campbell | L30: 33 | M30: Male | N30: =VLOOKUP(C:C,Customer_Dim!B:I,5,1) -> New Brian | O30: =VLOOKUP(C:C,Customer_Dim!B:I,6,1) -> Wisconsin | P30: =VLOOKUP(C:C,Customer_Dim!B:I,7,1) -> USA | Q30: =VLOOKUP(C:C,Customer_Dim!B:I,8,1) -> Bronze | S30: 2 | T30: 74.21 | U30: 0.11 | V30: 132.0938 | X30: 2 | Y30: 74.21 | Z30: 0.11 | AA30: 132.0938
A31: SALE29 | B31: 45302 | C31: CUST1348 | D31: PROD99 | E31: STORE3 | F31: 2.4776423 | G31: 451.67 | H31: 0.15 | I31: Credit Card | J31: 1535.678 | K31: Sherry Cabrera | L31: 31 | M31: Male | N31: =VLOOKUP(C:C,Customer_Dim!B:I,5,1) -> Shannonview | O31: =VLOOKUP(C:C,Customer_Dim!B:I,6,1) -> Pennsylvania | P31: =VLOOKUP(C:C,Customer_Dim!B:I,7,1) -> USA | Q31: =VLOOKUP(C:C,Customer_Dim!B:I,8,1) -> Silver | T31: 451.67 | U31: 0.15 | V31: 1535.678 | X31: 2.4776423 | Y31: 451.67 | Z31: 0.15 | AA31: 1535.678
A32: SALE30 | B32: 45217 | C32: CUST1028 | D32: PROD5 | E32: STORE19 | F32: 1 | G32: 429.38 | H32: 0.13 | I32: PayPal | J32: 373.5606 | K32: Joshua Ryan | L32: 54 | M32: Female | N32: =VLOOKUP(C:C,Customer_Dim!B:I,5,1) -> New David | O32: =VLOOKUP(C:C,Customer_Dim!B:I,6,1) -> New Jersey | P32: =VLOOKUP(C:C,Customer_Dim!B:I,7,1) -> USA | Q32: =VLOOKUP(C:C,Customer_Dim!B:I,8,1) -> Platinum | S32: 1 | T32: 429.38 | U32: 0.13 | V32: 373.5606 | X32: 1 | Y32: 429.38 | Z32: 0.13 | AA32: 373.5606
A33: SALE31 | B33: 45593 | C33: CUST1412 | D33: PROD53 | E33: STORE12 | F33: 2 | G33: 148.96 | H33: 0.03 | I33: COD | J33: 288.9824 | K33: Shane Brown | L33: 59 | M33: Female | N33: =VLOOKUP(C:C,Customer_Dim!B:I,5,1) -> East Andrea | O33: =VLOOKUP(C:C,Customer_Dim!B:I,6,1) -> Michigan | P33: =VLOOKUP(C:C,Customer_Dim!B:I,7,1) -> USA | Q33: =VLOOKUP(C:C,Customer_Dim!B:I,8,1) -> Gold | S33: 2 | T33: 148.96 | U33: 0.03 | V33: 288.9824 | X33: 2 | Y33: 148.96 | Z33: 0.03 | AA33: 288.9824
A34: SALE32 | B34: 45597 | C34: CUST1398 | D34: PROD75 | E34: STORE8 | F34: 4 | G34: 313.83 | H34: 0.08 | I34: Credit Card | J34: 1154.8944 | K34: Jennifer Johnson | L34: 27 | M34: Male | N34: =VLOOKUP(C:C,Customer_Dim!B:I,5,1) -> Cheyenneborough | O34: =VLOOKUP(C:C,Customer_Dim!B:I,6,1) -> New Hampshire | P34: =VLOOKUP(C:C,Customer_Dim!B:I,7,1) -> USA | Q34: =VLOOKUP(C:C,Customer_Dim!B:I,8,1) -> Bronze | S34: 4 | T34: 313.83 | U34: 0.08 | V34: 1154.8944 | X34: 4 | Y34: 313.83 | Z34: 0.08 | AA34: 1154.8944
A35: SALE33 | B35: 45620 | C35: CUST1453 | D35: PROD12 | E35: STORE6 | F35: 2 | G35: 717.31 | H35: 0.15 | I35: Credit Card | J35: 1219.427 | K35: April Phillips | L35: 60 | M35: Male | N35: =VLOOKUP(C:C,Customer_Dim!B:I,5,1) -> Lake Carolyn | O35: =VLOOKUP(C:C,Customer_Dim!B:I,6,1) -> Hawaii | P35: =VLOOKUP(C:C,Customer_Dim!B:I,7,1) -> USA | Q35: =VLOOKUP(C:C,Customer_Dim!B:I,8,1) -> Platinum | S35: 2 | T35: 717.31 | U35: 0.15 | V35: 1219.427 | X35: 2 | Y35: 717.31 | Z35: 0.15 | AA35: 1219.427
A36: SALE34 | B36: 45215 | C36: CUST1344 | D36: PROD79 | E36: STORE1 | F36: 2.4781059 | G36: 873.22 | H36: 0.18 | I36: Credit Card | J36: 2148.1212 | K36: Evelyn Brown | L36: 33 | M36: Male | N36: =VLOOKUP(C:C,Customer_Dim!B:I,5,1) -> West Victoriaborough | O36: =VLOOKUP(C:C,Customer_Dim!B:I,6,1) -> New Mexico | P36: =VLOOKUP(C:C,Customer_Dim!B:I,7,1) -> USA | Q36: =VLOOKUP(C:C,Customer_Dim!B:I,8,1) -> Gold | T36: 873.22 | U36: 0.18 | V36: 2148.1212 | X36: 2.4781059 | Y36: 873.22 | Z36: 0.18 | AA36: 2148.1212
A37: SALE35 | B37: 45878 | C37: CUST1218 | D37: PROD16 | E37: STORE3 | F37: 4 | G37: 109.36 | H37: 0.19 | I37: COD | J37: 354.3264 | K37: Julia Jackson | L37: 47 | M37: Female | N37: =VLOOKUP(C:C,Customer_Dim!B:I,5,1) -> Edwardland | O37: =VLOOKUP(C:C,Customer_Dim!B:I,6,1) -> California | P37: =VLOOKUP(C:C,Customer_Dim!B:I,7,1) -> USA | Q37: =VLOOKUP(C:C,Customer_Dim!B:I,8,1) -> Platinum | S37: 4 | T37: 109.36 | U37: 0.19 | V37: 354.3264 | X37: 4 | Y37: 109.36 | Z37: 0.19 | AA37: 354.3264
A38: SALE36 | B38: 45635 | C38: CUST1086 | D38: PROD5 | E38: STORE7 | F38: 3 | G38: 559.52 | H38: 0.16 | I38: PayPal | J38: 1409.9904 | K38: Tammy Miller Md | L38: 58 | M38: Female | N38: =VLOOKUP(C:C,Customer_Dim!B:I,5,1) -> Austinfurt | O38: =VLOOKUP(C:C,Customer_Dim!B:I,6,1) -> Mississippi | P38: =VLOOKUP(C:C,Customer_Dim!B:I,7,1) -> USA | Q38: =VLOOKUP(C:C,Customer_Dim!B:I,8,1) -> Gold | S38: 3 | T38: 559.52 | U38: 0.16 | V38: 1409.9904 | X38: 3 | Y38: 559.52 | Z38: 0.16 | AA38: 1409.9904
A39: SALE37 | B39: 45329 | C39: CUST1492 | D39: PROD10 | E39: STORE17 | F39: 3 | G39: 121.76 | H39: 0.27 | I39: PayPal | J39: 266.6544 | K39: Darrell Miller | L39: 28 | M39: Male | N39: =VLOOKUP(C:C,Customer_Dim!B:I,5,1) -> Port Carol | O39: =VLOOKUP(C:C,Customer_Dim!B:I,6,1) -> Florida | P39: =VLOOKUP(C:C,Customer_Dim!B:I,7,1) -> USA | Q39: =VLOOKUP(C:C,Customer_Dim!B:I,8,1) -> Platinum | S39: 3 | T39: 121.76 | U39: 0.27 | V39: 266.6544 | X39: 3 | Y39: 121.76 | Z39: 0.27 | AA39: 266.6544
A40: SALE38 | B40: 45378 | C40: CUST1189 | D40: PROD33 | E40: STORE13 | F40: 4 | G40: 735.32 | H40: 0.06 | I40: COD | J40: 2764.8032 | K40: Daniel Austin | L40: 21 | M40: Male | N40: =VLOOKUP(C:C,Customer_Dim!B:I,5,1) -> Lake Howardberg | O40: =VLOOKUP(C:C,Customer_Dim!B:I,6,1) -> Kentucky | P40: =VLOOKUP(C:C,Customer_Dim!B:I,7,1) -> USA | Q40: =VLOOKUP(C:C,Customer_Dim!B:I,8,1) -> Gold | S40: 4 | T40: 735.32 | U40: 0.06 | V40: 2764.8032 | X40: 4 | Y40: 735.32 | Z40: 0.06 | AA40: 2764.8032
...

Sheet Total Sales 
A1: Sales_ID | B1: Order_Date | C1: Customer_ID | D1: Product_ID | E1: Store_ID | F1: Quantity | G1: Unit_Price | H1: Discount | I1: Payment_Type | J1: Total_Amount | K1: Name | L1: Age | M1: Gender | N1: City | O1: State | P1: Country | Q1: Loyalty_Level | R1: Product_Name | S1: Category | T1: Sub_Category | U1: Brand | V1: Store_Name | W1: Region | X1: Store_Type
A2: SALE0 | B2: 45480 | C2: CUST1409 | D2: PROD97 | E2: STORE3 | F2: 1 | G2: 218.04 | H2: 0.09 | I2: Credit Card | J2: 198.4164 | K2: Sarah Smith | L2: 48 | M2: Female | N2: Kathleenport | O2: Wyoming | P2: USA | Q2: Gold | R2: Cricket Bat | S2: Sports | T2: Team Sports | U2: Khan LLC | V2: Johnson-Wright | W2: North | X2: Outlet
A3: SALE1 | B3: 45285 | C3: CUST1467 | D3: PROD74 | E3: STORE17 | F3: 3 | G3: 104.47 | H3: 0.27 | I3: PayPal | J3: 228.7893 | K3: Michael Foley | L3: 45 | M3: Male | N3: Oneillfurt | O3: Vermont | P3: USA | Q3: Gold | R3: Bluetooth Car Audio System | S3: Electronics | T3: Audio | U3: Bruce-Bowen | V3: Martinez, Adkins and Johnson | W3: North | X3: Flagship
A4: SALE2 | B4: 45446 | C4: CUST1056 | D4: PROD49 | E4: STORE8 | F4: 4 | G4: 914.05 | H4: 0.25 | I4: Credit Card | J4: 2742.15 | K4: Christopher Sutton | L4: 43 | M4: Female | N4: Deborahberg | O4: Pennsylvania | P4: USA | Q4: Gold | R4: Men's Roll-On Perfume | S4: Beauty | T4: Fragrance | U4: Sullivan and Sons | V4: Bean, Jones and Park | W4: West | X4: Online
A5: SALE3 | B5: 45259 | C5: CUST1346 | D5: PROD76 | E5: STORE8 | F5: 1 | G5: 921.51 | H5: 0.16 | I5: COD | J5: 774.0684 | K5: John Jordan | L5: 39 | M5: Female | N5: Port Crystalberg | O5: Tennessee | P5: USA | Q5: Platinum | R5: Wireless Mouse | S5: Electronics | T5: Computer | U5: Larson Ltd | V5: Bean, Jones and Park | W5: West | X5: Online
A6: SALE4 | B6: 45297 | C6: CUST1493 | D6: PROD59 | E6: STORE5 | F6: 3 | G6: 745.3 | H6: 0.18 | I6: Credit Card | J6: 1833.438 | K6: Amanda Powell | L6: 21 | M6: Male | N6: South William | O6: Alabama | P6: USA | Q6: Silver | R6: Men's Hair Styling Gel | S6: Beauty | T6: Haircare | U6: Cline-Mccarthy | V6: Gray Ltd | W6: North | X6: Outlet
A7: SALE5 | B7: 45499 | C7: CUST1116 | D7: PROD15 | E7: STORE7 | F7: 3 | G7: 147.01 | H7: 0.19 | I7: COD | J7: 357.2343 | K7: Anthony Phillips | L7: 21 | M7: Female | N7: North Davidport | O7: Rhode Island | P7: USA | Q7: Platinum | R7: 4K Home Projector | S7: Electronics | T7: Appliances | U7: Thomas LLC | V7: Martinez-Mullins | W7: South | X7: Online
A8: SALE6 | B8: 45850 | C8: CUST1016 | D8: PROD56 | E8: STORE4 | F8: 2 | G8: 785.31 | H8: 0.15 | I8: PayPal | J8: 1335.027 | K8: John Scott | L8: 60 | M8: Female | N8: South Christopher | O8: Pennsylvania | P8: USA | Q8: Bronze | R8: Premium Blanket Throw | S8: Home | T8: Decor | U8: Hernandez, Kennedy and Porter | V8: Alexander Group | W8: South | X8: Online
A9: SALE7 | B9: 45248 | C9: CUST1152 | D9: PROD70 | E9: STORE8 | F9: 4 | G9: 342.39 | H9: 0.23 | I9: PayPal | J9: 1054.5612 | K9: Patrick Roberts | L9: 31 | M9: Male | N9: Jaredville | O9: Missouri | P9: USA | Q9: Platinum | R9: Kitchen Storage Rack | S9: Home | T9: Storage | U9: Duran Group | V9: Bean, Jones and Park | W9: West | X9: Online
A10: SALE8 | B10: 45781 | C10: CUST1187 | D10: PROD99 | E10: STORE5 | F10: 2.4796175 | G10: 448.25 | H10: 0.07 | I10: PayPal | J10: 1250.6175 | K10: Dr. Suzanne Bullock | L10: 42 | M10: Male | N10: Lake Blaketon | O10: Alabama | P10: USA | Q10: Platinum | R10: Stainless Steel Cookware Set | S10: Home | T10: Kitchen | U10: Campbell Ltd | V10: Gray Ltd | W10: North | X10: Outlet
A11: SALE9 | B11: 45869 | C11: CUST1464 | D11: PROD33 | E11: STORE0 | F11: 2 | G11: 873.17 | H11: 0.23 | I11: PayPal | J11: 1344.6818 | K11: David Pierce | L11: 28 | M11: Female | N11: Grayland | O11: Washington | P11: USA | Q11: Platinum | R11: Modern Wall Clock | S11: Home | T11: Decor | U11: Weiss-Watson | V11: Rivera-Warner | W11: East | X11: Flagship
A12: SALE10 | B12: 45335 | C12: CUST1065 | D12: PROD24 | E12: STORE14 | F12: 1 | G12: 278.63 | H12: 0.07 | I12: Credit Card | J12: 259.1259 | K12: Michael Thomas | L12: 27 | M12: Female | N12: Woodmouth | O12: Nevada | P12: USA | Q12: Silver | R12: Foldable Camping Chair | S12: Sports | T12: Outdoor | U12: Cook Ltd | V12: Martinez, Adkins and Johnson | W12: North | X12: Flagship
A13: SALE11 | B13: 45801 | C13: CUST1320 | D13: PROD39 | E13: STORE1 | F13: 4 | G13: 286.92 | H13: 0.17 | I13: Credit Card | J13: 952.5744 | K13: Jessica Gonzalez | L13: 21 | M13: Female | N13: South Darrenland | O13: Iowa | P13: USA | Q13: Bronze | R13: Portable Power Bank | S13: Electronics | T13: Mobile | U13: Cummings and Sons | V13: Martinez, Adkins and Johnson | W13: North | X13: Flagship
... A2001: SALE1999 | B2001: 45267 | C2001: CUST1023 | D2001: PROD76 | E2001: STORE19 | F2001: 3 | G2001: 68.45 | H2001: 0.17 | I2001: PayPal | J2001: 170.4405 | K2001: Jonathan Steele | L2001: 40 | M2001: Male | N2001: Molinabury | O2001: Oregon | P2001: USA | Q2001: Silver | R2001: Wireless Mouse | S2001: Electronics | T2001: Computer | U2001: Larson Ltd | V2001: Martinez, Adkins and Johnson | W2001: North | X2001: Flagship

Sheet Analysis
D4: Total No of Sales | E4: =COUNT(Table7[Total_Amount]) -> 2000
D5: Male Sales Count | E5: =COUNTIF(Table7[Gender],"Male") -> 968
D6: Female Sales Count | E6: =COUNTIF(Table7[Gender],"Female") -> 1032
D7: Total Sales Amount | E7: =SUM(Table7[Total_Amount]) -> 2175265

Sheet pivot Tables 
A1: Name | B1: Order_Date | C1: Total_Amount | D1: Payment_Type | E1: Age | F1: Gender | G1: Category | H1: Region | L1: Order_Date | M1: Total_Amount | R1: Payment_Type | S1: Total_Amount | W1: Gender | X1: Category | Y1: Total_Amount | AF1: Total_Amount | AG1: Region
A2: Sarah Smith | B2: 45480 | C2: 198.4164 | D2: Credit Card | E2: 48 | F2: Female | G2: Sports | H2: North | L2: 45480 | M2: 198.4164 | O2: Row Labels | P2: Sum of Total_Amount | R2: Credit Card | S2: 198.4164 | W2: Female | X2: Sports | Y2: 198.4164 | AF2: 198.4164 | AG2: North
A3: Michael Foley | B3: 45285 | C3: 228.7893 | D3: PayPal | E3: 45 | F3: Male | G3: Electronics | H3: North | L3: 45285 | M3: 228.7893 | O3: 2023 | P3: 224167.89 | R3: PayPal | S3: 228.7893 | T3: Row Labels | U3: Sum of Total_Amount | W3: Male | X3: Electronics | Y3: 228.7893 | Z3: Sum of Total_Amount | AA3: Column Labels | AF3: 228.7893 | AG3: North
A4: Christopher Sutton | B4: 45446 | C4: 2742.15 | D4: Credit Card | E4: 43 | F4: Female | G4: Beauty | H4: West | L4: 45446 | M4: 2742.15 | O4: 2024 | P4: 1093875.3 | R4: Credit Card | S4: 2742.15 | T4: COD | U4: 703703.34 | W4: Female | X4: Beauty | Y4: 2742.15 | Z4: Row Labels | AA4: Female | AB4: Male | AC4: Grand Total | AF4: 2742.15 | AG4: West | AH4: Row Labels | AI4: Sum of Total_Amount
A5: John Jordan | B5: 45259 | C5: 774.0684 | D5: COD | E5: 39 | F5: Female | G5: Electronics | H5: West | L5: 45259 | M5: 774.0684 | O5: 2025 | P5: 857221.8 | R5: COD | S5: 774.0684 | T5: Credit Card | U5: 714843.57 | W5: Female | X5: Electronics | Y5: 774.0684 | Z5: Beauty | AA5: 180344.28 | AB5: 175735.69 | AC5: 356079.97 | AF5: 774.0684 | AG5: West | AH5: East | AI5: 199672.35
A6: Amanda Powell | B6: 45297 | C6: 1833.438 | D6: Credit Card | E6: 21 | F6: Male | G6: Beauty | H6: North | L6: 45297 | M6: 1833.438 | O6: Grand Total | P6: 2175265 | R6: Credit Card | S6: 1833.438 | T6: PayPal | U6: 756718.1 | W6: Male | X6: Beauty | Y6: 1833.438 | Z6: Clothing | AA6: 155935.59 | AB6: 166848.67 | AC6: 322784.26 | AF6: 1833.438 | AG6: North | AH6: North | AI6: 1380704.5
A7: Anthony Phillips | B7: 45499 | C7: 357.2343 | D7: COD | E7: 21 | F7: Female | G7: Electronics | H7: South | L7: 45499 | M7: 357.2343 | R7: COD | S7: 357.2343 | T7: Grand Total | U7: 2175265 | W7: Female | X7: Electronics | Y7: 357.2343 | Z7: Electronics | AA7: 281133.04 | AB7: 222031.8 | AC7: 503164.84 | AF7: 357.2343 | AG7: South | AH7: South | AI7: 435916.67
A8: John Scott | B8: 45850 | C8: 1335.027 | D8: PayPal | E8: 60 | F8: Female | G8: Home | H8: South | L8: 45850 | M8: 1335.027 | R8: PayPal | S8: 1335.027 | W8: Female | X8: Home | Y8: 1335.027 | Z8: Home | AA8: 217025.26 | AB8: 231524.56 | AC8: 448549.82 | AF8: 1335.027 | AG8: South | AH8: West | AI8: 158971.46
A9: Patrick Roberts | B9: 45248 | C9: 1054.5612 | D9: PayPal | E9: 31 | F9: Male | G9: Home | H9: West | L9: 45248 | M9: 1054.5612 | R9: PayPal | S9: 1054.5612 | W9: Male | X9: Home | Y9: 1054.5612 | Z9: Sports | AA9: 276719.29 | AB9: 267966.82 | AC9: 544686.11 | AF9: 1054.5612 | AG9: West | AH9: Grand Total | AI9: 2175265
A10: Dr. Suzanne Bullock | B10: 45781 | C10: 1250.6175 | D10: PayPal | E10: 42 | F10: Male | G10: Home | H10: North | L10: 45781 | M10: 1250.6175 | R10: PayPal | S10: 1250.6175 | W10: Male | X10: Home | Y10: 1250.6175 | Z10: Grand Total | AA10: 1111157.5 | AB10: 1064107.5 | AC10: 2175265 | AF10: 1250.6175 | AG10: North
A11: David Pierce | B11: 45869 | C11: 1344.6818 | D11: PayPal | E11: 28 | F11: Female | G11: Home | H11: East | L11: 45869 | M11: 1344.6818 | R11: PayPal | S11: 1344.6818 | W11: Female | X11: Home | Y11: 1344.6818 | AF11: 1344.6818 | AG11: East
A12: Michael Thomas | B12: 45335 | C12: 259.1259 | D12: Credit Card | E12: 27 | F12: Female | G12: Sports | H12: North | L12: 45335 | M12: 259.1259 | R12: Credit Card | S12: 259.1259 | W12: Female | X12: Sports | Y12: 259.1259 | AF12: 259.1259 | AG12: North
A13: Jessica Gonzalez | B13: 45801 | C13: 952.5744 | D13: Credit Card | E13: 21 | F13: Female | G13: Electronics | H13: North | L13: 45801 | M13: 952.5744 | R13: Credit Card | S13: 952.5744 | W13: Female | X13: Electronics | Y13: 952.5744 | AF13: 952.5744 | AG13: North
A14: Wesley Short | B14: 45528 | C14: 2552.5368 | D14: Credit Card | E14: 40 | F14: Male | G14: Sports | H14: South | L14: 45528 | M14: 2552.5368 | R14: Credit Card | S14: 2552.5368 | W14: Male | X14: Sports | Y14: 2552.5368 | AF14: 2552.5368 | AG14: South
A15: Adam Castro | B15: 45875 | C15: 443.66 | D15: PayPal | E15: 19 | F15: Male | G15: Electronics | H15: North | L15: 45875 | M15: 443.66 | R15: PayPal | S15: 443.66 | W15: Male | X15: Electronics | Y15: 443.66 | AF15: 443.66 | AG15: North
A16: Sherry Cabrera | B16: 45829 | C16: 1145.8548 | D16: PayPal | E16: 31 | F16: Male | G16: Sports | H16: North | L16: 45829 | M16: 1145.8548 | R16: PayPal | S16: 1145.8548 | W16: Male | X16: Sports | Y16: 1145.8548 | AF16: 1145.8548 | AG16: North
A17: Lindsay Beasley | B17: 45636 | C17: 2509.4592 | D17: COD | E17: 61 | F17: Male | G17: Clothing | H17: South | L17: 45636 | M17: 2509.4592 | R17: COD | S17: 2509.4592 | W17: Male | X17: Clothing | Y17: 2509.4592 | AF17: 2509.4592 | AG17: South
A18: Arthur Warren | B18: 45913 | C18: 677.97 | D18: Credit Card | E18: 22 | F18: Female | G18: Sports | H18: North | L18: 45913 | M18: 677.97 | R18: Credit Card | S18: 677.97 | W18: Female | X18: Sports | Y18: 677.97 | AF18: 677.97 | AG18: North
A19: Molly Gardner | B19: 45637 | C19: 774.1426 | D19: Credit Card | E19: 61 | F19: Female | G19: Home | H19: South | L19: 45637 | M19: 774.1426 | R19: Credit Card | S19: 774.1426 | W19: Female | X19: Home | Y19: 774.1426 | AF19: 774.1426 | AG19: South
A20: David Patterson | B20: 45517 | C20: 838.845 | D20: COD | E20: 62 | F20: Female | G20: Electronics | H20: South | L20: 45517 | M20: 838.845 | R20: COD | S20: 838.845 | W20: Female | X20: Electronics | Y20: 838.845 | AF20: 838.845 | AG20: South
A21: Maria Hill | B21: 45369 | C21: 1782.4512 | D21: COD | E21: 59 | F21: Female | G21: Beauty | H21: North | L21: 45369 | M21: 1782.4512 | R21: COD | S21: 1782.4512 | W21: Female | X21: Beauty | Y21: 1782.4512 | AF21: 1782.4512 | AG21: North
A22: Justin Cross | B22: 45843 | C22: 2159.4276 | D22: COD | E22: 46 | F22: Male | G22: Sports | H22: North | L22: 45843 | M22: 2159.4276 | R22: COD | S22: 2159.4276 | W22: Male | X22: Sports | Y22: 2159.4276 | AF22: 2159.4276 | AG22: North
... A2001: Jonathan Steele | B2001: 45267 | C2001: 170.4405 | D2001: PayPal | E2001: 40 | F2001: Male | G2001: Electronics | H2001: North | L2001: 45267 | M2001: 170.4405 | R2001: PayPal | S2001: 170.4405 | W2001: Male | X2001: Electronics | Y2001: 170.4405 | AF2001: 170.4405 | AG2001: North

Sheet Dashboard
